# 18장 - 오류처리와 테스트


# 코루틴 내부에서 throw된 오류 처리

- launch 나 async 호출을 try-catch로 감싸도 의미가 없다
    - 코루틴 빌더 함수이기 때문
    - 코루틴에서 발생한 예외는 catch 로 안잡힌다.
        
        ```kotlin
        fun exec_error() : Unit = runBlocking{
            try {
                launch {
                    throw UnsupportedOperationException("error")
                }
            }    catch (u: UnsupportedOperationException){
                println("Handled $u")
            }
        }
        Exception in thread "main" java.lang.UnsupportedOperationException: error
        	at org.example.error_handling.ErrorHandlingInKorutineKt$exec_error$1$1.invokeSuspend(ErrorHandlingInKorutine.kt:10)
        	at kotlin.coroutines.jvm.internal.BaseContinuationImpl.resumeWith(ContinuationImpl.kt:33)
        	at kotlinx.coroutines.DispatchedTask.run(DispatchedTask.kt:108)
        	at kotlinx.coroutines.EventLoopImplBase.processNextEvent(EventLoop.common.kt:280)
        	at kotlinx.coroutines.BlockingCoroutine.joinBlocking(Builders.kt:85)
        	at kotlinx.coroutines.BuildersKt__BuildersKt.runBlocking(Builders.kt:59)
        	at kotlinx.coroutines.BuildersKt.runBlocking(Unknown Source)
        	at kotlinx.coroutines.BuildersKt__BuildersKt.runBlocking$default(Builders.kt:38)
        ```
        
- 처리 방법
    - launch에 전달되는 람다 블록 안에 try-catch ⇒ throw가 코루틴의 경계를 넘어가지 않는다.
        
        ```kotlin
        fun exec_error_handle(): Unit = runBlocking {
            launch {
                try {
                    throw UnsupportedOperationException("error")
                } catch (u: UnsupportedOperationException) {
                    println("Handled $u")
                }
            }
        }
        
        Handled java.lang.UnsupportedOperationException: error
        
        ```
        
- async로 생성된 코루틴이 throw 하는 경우
    - await가 원하는 타입의 의미 있는 값을 return 할 수 없어서, 예외를 던져야한다.
        
        ```kotlin
        fun exec_await_error(): Unit = runBlocking {
            val myDeferredInt: Deferred<Int> = async {
                throw UnsupportedOperationException("Ouch!")
            }
                try {
                    val i: Int = myDeferredInt.await()
                    println(i)
                } catch (u: UnsupportedOperationException) {
                    println("Handled: $u")
                }
        }
        
        Exception in thread "main" java.lang.UnsupportedOperationException: Ouch!
        	at org.example.error_handling.ErrorHandlingInKorutineKt$exec_await_error$1$myDeferredInt$1
        	.invokeSuspend(ErrorHandlingInKorutine.kt:31)
        ```
        
    
    ⇒ awiat가 예외를 다시 throw 했으나, 원래의 예외도 관찰되기 때문
    async 는 부모 코루틴인 runBlocking에 예외를 전파 후 프로그램 종료
    
    - 자식 코루틴은 catch 되지 않은 예외를 항상 부모 코루틴에 전파한다.
    - 부모 코루틴은 이 예외를 처리해야 할 책임을 가진다.

# 코틀린 코루틴에서의 오류 전파

- 자식 중 하나의 실패가 부모의 실패로 이어질 것인지에 따라 나뉜다.
    - 코루틴이 작업을 동시적으로 분해해 처리하는 경우 → 자식 중 하나의 실패는 부모의 실패
    - 하나의 자식이 실패해도 전체 실패는 아닌 경우 → 시스템 전체가 실패하면 안되는경우
        - 최신 데이터를 가져오는 작업 이 실패해도 UI 구성 요소는 계속 살아 있어야 한다.
    

## 한 개의 자식이 실패 → 모두의 실패 → 모든 자식 취소

- SupervisorJob 없이 생성된 경우, 코루틴에서 발생한 uncaught 예외는, 부모 코루틴을 예외로 완료시키는 방식으로 처리
- 실패한 자식 → 부모에게 예외 전파
    
    <img width="563" height="211" alt="image" src="https://github.com/user-attachments/assets/b902962e-66d1-4d46-91c5-ce234698530f" />

    - 부모의 실행 사항
        - 다른 모든 자식 취소
        - 같은 예외 발생 → 자신의 실행 완료
        - 자신의 상위 계층으로 예외 전파
- 일반적으로 다른 언어는 이 부분을 개발자가 구현해야한다 → 코루틴은 해준다

## 예시

```kotlin
fun main(): Unit = runBlocking {
    launch {
        try {
            while(true){ // 하트피트 500밀리초마다 print
                println("Heartbeat!")
                delay(500.milliseconds)
            }
        }catch (e:Exception){
            println("Heartbeat terminated: $e")
            throw e
        }
    }
    launch {
        delay(1.seconds)// 1초가 지난 후 예외 발생
        throw UnsupportedOperationException("Siuuuuuu") // 예외를 catch 하지 않음
    }
}
```

```kotlin
Heartbeat!
Heartbeat!
Heartbeat terminated: kotlinx.coroutines.JobCancellationException: Parent job is Cancelling; job=BlockingCoroutine{Cancelling}@ea4a92b
```

- 형제 코루틴 중 하나가 예외를 던지면, heartbeat 도 취소

⇒ runBlocking 을 포함한 모든 코루틴 빌더는, 
한 코루틴이 잡히지 않은 예외로 종료되면 다른 자식 코루틴도 취소된다.

- launch → async 로 바꿔도 똑같다.

## 구조적 동시성은 코루틴 스코프를 넘는 예외에만 영향을 미친다

- 형제 코루틴 취소 → 예외를 코루틴 계층 상위로 전파
    - 이 동작은 코루틴 스코프를 넘는 처리되지 않은 예외에만 영향을 미친다.
        
        ```kotlin
        fun main(): Unit = runBlocking {
            launch {
                try {
                    while (true) {
                        println("Heartbeat!")
                        delay(500.milliseconds)
                    }
                } catch (e: Exception) {
                    println("Heartbeat terminated: $e")
                    throw e
                }
            }
            launch {
                try {
                    delay(1.seconds)
                    throw UnsupportedOperationException("Siuuuuuu")
                } catch (u: UnsupportedOperationException) {
                    println("Caught $u")
                }
            }
        }
        
        Heartbeat!
        Heartbeat!
        Caught java.lang.UnsupportedOperationException: Siuuuuuu
        Heartbeat!
        Heartbeat!
        ```
        
        - 형제 스코프에는 영향을 주지 않는다.

## Supervisor - 예외가 전파되지 않도록 한다

- 부모와 형제가 취소되지 않게 한다.
    
    <img width="535" height="177" alt="image 1" src="https://github.com/user-attachments/assets/9f6e5289-3475-4c80-a1c5-956148429e2b" />

- 자식이 실패하더라도 생존한다.
- 일반 Job과 달리, 일부 자식이 실패를 보고하더라도 실패하지 않는다.
- 예외를 상위로 전파하지 않는다.

## 예시

```kotlin

fun main(): Unit = runBlocking {
    supervisorScope {
        launch {
            try {
                while (true) {
                    println("Heartbeat!")
                    delay(500.milliseconds)
                }
            } catch (e: Exception) {
                println("Heartbeat terminated: $e")
                throw e
            }
        }
        launch {
            delay(1.seconds)
            throw UnsupportedOperationException("Siuuuuuu")
        }
    }
}

Heartbeat!
Heartbeat!
Exception in thread "main" java.lang.UnsupportedOperationException: Siuuuuuu
	Suppressed: kotlinx.coroutines.internal.DiagnosticCoroutineContextException: [StandaloneCoroutine{Cancelling}@3cda1055, BlockingEventLoop@7a5d012c]
Heartbeat!
Heartbeat!
Heartbeat!
Heartbeat!
```

## 왜?

- SupervisorJob 이 launch 빌더로 시작된 자식 코루틴에 대해 CoroutineExceptionHandler 를 호출하기 때문

- Supervisor 는 애플리케이션에서 코루틴 계층의 “위쪽”에 위치하는 경우가 많다
    - 전체 수명이나 창 또는 뷰가 사용자에게 표시되는 시간과 같이,
    계속 살아남아 실행되어야 하는 부분이기 때문
    - 미세한 작업 함수들은 일반적으로 사용하지 않는다.→불필요한 작업은 취소되는게 맞지

# CoroutineExceptionHandler - 예외 처리를 위한 마지막 수단

자식 코루틴 → 처리되지 않은 예외 → 부모 코루틴에 전파

→ 슈퍼바이저에 도달 하거나

→ 계층의 최상위 → 부모가 없는 루트 코루틴

⇒ 이렇게 끝까지 예외가 도달하면 전파가 끝난다.

- 전파가 끝난 후 처리되지 않은 예외는 Coroutine ExceptionHandler라는 특별한 핸들러에게 전달
- 이 핸들러는 코루틴 컨텍스트의 일부다.
- 코루틴 컨텍스트에  예외 핸들러가 없다면 → 에러는 시스템 전역 예외 핸들러로 이동

## 예시

```kotlin
class ComponentWithScope(dispatcher: CoroutineDispatcher = Dispatchers.Default){
    private val exceptionHandler = CoroutineExceptionHandler { _, e ->
        println("[ERROR] ${e.message}")//4
    }
    private val scope = CoroutineScope(SupervisorJob() + dispatcher + exceptionHandler)

    fun action() = scope.launch { throw UnsupportedOperationException("SIUUU") }//3
}

fun main() = runBlocking {
  val supervisor  = ComponentWithScope()//1
    supervisor.action()//2
    delay(1.seconds)
}

[ERROR] SIUUU

```

- 출력 결과가 직접 정의한 커스텀 exception handler에 의해 처리된다.
- 코루틴 예외 핸들러는 
코루틴 계층에서 최상위 코루틴이 launch 빌더로 시작된 경우에만 호출된다.

## 주의사항 - 루트 코루틴이 아니면 예외 핸들러는 의미가 없다

자식 코루틴 → 처리되지 않은 예외 → 부모에게 위임 → 최상위까지 반복

중간에 잇는 CoroutineExceptionHandler 라는 것은 존재하지 않는다.

루트 코루틴이 아닌 코루틴의 콘텍스트에 설치된 핸들러는 결코 사용되지 않는다.

### 예시

```kotlin
private val topLevelHandler = CoroutineExceptionHandler { _, e -> println("[TOP] ${e.message}") }
private val intermediateErrorHandler = CoroutineExceptionHandler { _, e -> println("[INTERMEDIATE] ${e.message}") }

@OptIn(DelicateCoroutinesApi::class)
fun main() {
    GlobalScope.launch(topLevelHandler) {
        launch(intermediateErrorHandler){
            throw UnsupportedOperationException("SIUU")
        }
    }
    Thread.sleep(1000)
}

[TOP] SIUU

종료 코드 0(으)로 완료된 프로세스
```

### WHY?

<img width="813" height="407" alt="image 2" src="https://github.com/user-attachments/assets/ee7d2306-ace0-497d-8aa6-a69a7845a3e9" />

- 예외가 여전히 부모 코루틴에게 전파될 수 있기 때문
- 중간의 lauch 호출에 코루틴 예외 핸들러가 있음에도 루트 코루틴이 아니기 때문에,
예외가 계속 상위 계층으로 전파된다.

## launch 와 async에 적용할 때의 차이점

- 최상위 코루틴이 `async`로 생성된 경우에는 `CoroutineExceptionHandler`가 호출되지 않는다.

### 예제

```kotlin
class ComponentWithScope(dispatcher: CoroutineDispatcher = Dispatchers.Default) {
    private val exceptionHandler = CoroutineExceptionHandler { _, e ->
        println("[ERROR] ${e.message}")
    }
    private val scope = CoroutineScope(
        SupervisorJob() + dispatcher + exceptionHandler
    )

    fun action() = scope.launch {
        async {
            throw UnsupportedOperationException("SIUU!")
        }
    }
}

fun main() = runBlocking {
    val supervisor = ComponentWithScope2()
    supervisor.action()
    delay(1.seconds)
}

[ERROR] SIUU!

```

```kotlin
class ComponentWithScope(dispatcher: CoroutineDispatcher = Dispatchers.Default) {
...
    fun action() = scope.async {
        launch {
            throw UnsupportedOperationException("SIUU!")
        }
    }
}

fun main() = runBlocking {
    val supervisor = ComponentWithScope()
    supervisor.action()
    delay(1.seconds)
}

```

⇒ 출력 없음

- 최상위 코루틴이 async 로 시작되면, 예외를 처리하는 책임은 `await( )` 를 호출하는 `Deferred` 의 소비자에게 있다.
- 코루틴 예외 핸들러는, 이 예외를 무시할 수 있다.
- await 호출을 try-catch 로 감싸서 예외처리 할 수 있다.
    - 이 경우에는 try-catch 가 코루틴 취소에 영향을 끼치지 못한다.
        
        ```kotlin
            private val scope = CoroutineScope(
                SupervisorJob() + dispatcher + exceptionHandler
            )
        ```
        
        - scope에 SupervisorJob이 있기때문

# 플로우에서 예외 처리

- flow 의 일부분에서 예외가 발생하면 collect에서 예외가 던져진다.
- collect 호출을 try-catch 로 감싸면 처리가 가능하다.
- 플로우 중간 연산자가 적용되었는지 여부와는 관계가 없다
- 플로우 collect 5개의 원소 emit 후 exception
    
    ```kotlin
    class unHappyFlowException: Exception()
    
    val exceptionalFlow = flow {
        repeat(5) {
            number -> emit(number)
        }
        throw unHappyFlowException()
    }
    
    fun exec_flow_error() = runBlocking {
        val transformedFlow = exceptionalFlow.map { it * 2 }
        try {
            transformedFlow.collect {
                print("$it ")
            }
        } catch (u: unHappyFlowException) {
            println("\nHandled: $u")
        }
    }
    
    0 2 4 6 8 
    Handled: org.example.error.handling.unHappyFlowException
    ```
    

⇒ 복잡하고 긴 플로우 파이프라인 구축시, catch 연산자를 사용하는게 더 편리하다.

## catch로 업스트림 예외 처리

- catch 는 플로우에서 발생한 예외를 처리할 수 있는 중간 연산자
- 예외는 람다의 파라미터로 전달된다.
- 취소 예외를 자동으로 인식 → 취소가 발생한 경우에는 catch 블록이 호출되지 않는다.
- catch는 스스로 emit할 수 있기 때문에, 예외를 오류 값으로 변환해서 다운스트림 플로우에서 소비할 수 있다.
    
    ```kotlin
    val exceptionalFlow = flow {
        repeat(5) {
            number -> emit(number)
        }
        throw unHappyFlowException()
    }
    
    fun exec_catch_upstream() = runBlocking {
        exceptionalFlow
            .catch {
                cause -> println("\nHandled: $cause")
                emit(-1)
            }
            .collect{
                print("$it ")
            }
    }
    
    0 1 2 3 4 
    Handled: org.example.error.handling.unHappyFlowException
    -1 
    ```
    
    - exceptionalFlow에서 발생한 예외
    - 로그에 기록
    - collect에 오류 값으로 -1 emit
    
    ⇒ catch 연산자는, 오직 업스트림에 대해서만 작동
    플로우 처리 파이프라인 앞쪽에서 발생한 예외만 잡는다.
    
    ```kotlin
    fun exec_catch_upstream_fail() = runBlocking {
        exceptionalFlow
            .map { it + 1 }
            .catch {
                    cause -> println("\nHandled: $cause")
            }
            .onEach {
                throw UnHappyFlowException()
            }
            .collect {
                print("$it ")
            }
    }
    
    Exception in thread "main" org.example.error.handling.UnHappyFlowException
    ```
    

<img width="694" height="215" alt="image 3" src="https://github.com/user-attachments/assets/65b99ad9-ce94-473e-98a8-39ead336518c" />

- catch 연산자는 업스트림에서 발생한 예외만 처리
- 예외를 catch 블록에서 다시 던져서 다운스트림에 있는 다른 catch 연산자에서 처리하게 하는 것도 완전히 올바른 코드다 .

## Flow 수집 재시도 : retry

- retry 도 catch 처럼 업스트림의 예외를 잡는다.
- 예외를 처리하고 Boolean 값을 반환하는 람다를 사용할 수 있다.
    - 람다가 true 반환시 재시도 ⇒ 업스트림의 플로우가 처음부터 다시 수집, 모든 중간 연산이 다시 실행

### 예제

- 목표는 0~9까지 출력
- 0.1 이 나오면 계속 다시 시작
    - 최대 5번

```kotlin
val unreliableFlow = flow {
    println("Starting the flow!")
    repeat(10) { number ->
        if (Random.nextDouble() < 0.1) throw CommunicationException()
        emit(number)
    }
}

fun exec_unreliable_flow() = runBlocking {
    unreliableFlow
        .retry(5) { cause ->
            println("\nHandled: $cause")
            cause is CommunicationException
        }
        .collect { number ->
            print("$number ")
        }
}

Starting the flow!
0 1 2 3 4 
Handled: org.example.error.handling.CommunicationException: Communication failed!
Starting the flow!
0 1 2 3 4 
Handled: org.example.error.handling.CommunicationException: Communication failed!
Starting the flow!
0 1 2 3 4 5 6 7 8 9 
```

### 기억해야할 것

- 재시도시 업스트림 연산자가 모두 다시 실행된다.
- 멱등성을 갖거나, 반복 실행이 올바르게 처리 되는지 확인

---

# 코루틴과 플로우 테스트

- 테스트 메서드에서 코루틴 사용하려면 runTest 코루틴 빌더 사용
- runBlocking을 쓰면, delay가 지정된 경우 결과가 계산되기 전에 시간 지연이 전부 실행된다.

## 가상 시간과 테스트 디스패처

- 

```kotlin
class TestSandbox {

    @Test
    fun testDelay() = runTest {
        val startTime = System.currentTimeMillis()
        delay(20.seconds)
        println(System.currentTimeMillis() - startTime)
    }
}

1
```

- runTest
    - 가상 시간으로 테스트 실행
    - 20초를 delay 했음에도 테스트는 실질적으로 즉시 실행
    - 타임아웃 디폴트로 60초가 지정된다. ⇒ runTest 호출 시 timeout 파라미터 지정 가능
- runTest 의 디스패처는 단일 스레드
    - 모든 자식 코루틴은 동시에 실행 → 테스트 코드와 병렬로 실행되지 않는다.

- 단일 스레드 디스패처를 공유하는 경우, 다른 코루틴이 코드를 실행하려면, 코드가 일시 중단 지점을 제공해야한다.
    - runTest 본문에 일시 중단 지점이 없기 때문에 다음 테스트의 단언문은 실패한다.
    
    ⇒ launch로 시작한 코루틴이 단언문이 실행되기 전에 실행되게 할 수 있는 방법이 없다.
    
    ```kotlin
        @Test
        fun testDelay2() = runTest{
            var x = 0
            launch { x++ }
            launch { x++ }
            assertEquals(2, x)
        }
        
    org.opentest4j.AssertionFailedError: 
    필요:2
    실제   :0
    ```
    
    - `delay( )`, `yield( )`, 다른 일시 중단 함수 호출을 추가해서 테스트를 통과시킬 수 있다.
        
        ```kotlin
            @OptIn(ExperimentalCoroutinesApi::class)
            @Test
            fun testDelay3() = runTest{
                var x = 0
                launch {
                    delay(500.milliseconds)
                    x++
                }
                launch {
                    delay(1.seconds)
                    x++
                }
                println(currentTime) // 0
        
                delay(600.milliseconds)
                assertEquals(1, x)
                println(currentTime) // 600
        
                delay(500.milliseconds)
                assertEquals(2, x)
                println(currentTime) // 1100
            }
            //테스트 통과
        ```
        
    - 테스트 디스패처에서는 `TestCoroutineScheduler`를 통해 가상 시간을 더 세밀하게 제어할 수 있다.
    - runTest 빌더 함수의 블록 안에서는 `TestScope` (특수 스코프)에 접근할 수 있다
        
        ```kotlin
            @OptIn(ExperimentalCoroutinesApi::class)
            @Test
            fun testDelay4() = runTest{
                var x = 0
                launch {
                    x++
                    launch { x++ }
                }//runCurrent 여기까지 실행
                launch {//advanceUntilIdle 아래로 더 실행
                    delay(200.milliseconds)
                    x++
                }
                runCurrent() // 현재 실행하도록 예약된 코루틴 실행
                assertEquals(2, x)
                advanceUntilIdle()// 모든 예약된 코루틴 실행
                assertEquals(3, x)
            }
        ```
        
        - 이 스코프는 `TestCoroutineScheduler` 기능을 사용할 수 있게 해준다
        - `TestCoroutineScheduler`  의 핵심 함수는 다음과 같다
            - `runCurrent` : 현재 실행하게 예약된 모든 코루틴 실행
            - `advanceUntilIdle` : 예약된 모든 코루틴 실행
    
    # 터빈으로 플로우 테스트
    
    - toList를 호출해서 유한한 플로우의 모든 원소를 먼저 collection 에 수집하고,
    assertion을 할 수 있다
    
    ```kotlin
        val myFlow = flow {
            emit(1)
            emit(2)
            emit(3)
        }
    
        @Test
        fun doTest() = runTest {
            val results = myFlow.toList()
            assertEquals(3, results.size)
        }
    ```
    
    ```kotlin
    @Test
    fun doTest() = runTest {
    	val results = myFlow.test {
    		assertEquals(1, awaitItem())
    		assertEquals(2, awaitItem())
    		assertEquals(3, awaitItem())
    		awaitComplete( )
    	}
    }
    
    ```
    
    - 터빈의 핵심 기능은 플로우의 확장 함수인 test 함수다
        - test 함수는 새 코루틴을 실행
        - 내부적으로 플로우를 수집한다
    - test의 람다에서 `awaitltem`, `awaitComplete`, `awaitError`  함수를 테스트 프레임워크의 일반 단언문과 함께 사용 
    ⇒ 플로우에 대한 불변 조건을 지정하고 검증 
    또한 플로우가 방출한 모든 원소가 테스트에 의해 적절히 소비되도록 보장한다．

# 문제
다음 중 `supervisorScope`를 사용하는 이유로 올바른 것을 모두 고르세요.

A. 자식 코루틴 중 하나가 실패해도 다른 자식 코루틴의 실행을 유지하기 위해

B. 모든 예외를 CoroutineExceptionHandler로 전달하기 위해

C. 부모 코루틴의 예외가 자식 코루틴에 전파되지 않도록 하기 위해

D. 자식 코루틴의 예외가 상위 코루틴으로 전파되지 않도록 하기 위해

================================

답

A. 자식 코루틴 중 하나가 실패해도 다른 자식 코루틴의 실행을 유지하기 위해

 D. 자식 코루틴의 예외가 상위 코루틴으로 전파되지 않도록 하기 위해





다음 코드를 실행했을 때 출력 결과는?

```kotlin
fun main() = runBlocking {
    launch {
        try {
            while (true) {
                println("Heartbeat!")
                delay(500)
            }
        } catch (e: Exception) {
            println("Heartbeat terminated: $e")
            throw e
        }
    }

    launch {
        delay(1000)
        throw UnsupportedOperationException("Siuuuuuu")
    }
}

```

정답

=====================================





 ```kotlin
Heartbeat!
Heartbeat!
Heartbeat terminated: kotlinx.coroutines.JobCancellationException: Parent job is Cancelling; ...
```

